Workbook
Name SegmentaçãoDeDados_Ano: #N/A
Name SegmentaçãoDeDados_Mês: #N/A
Name SegmentaçãoDeDados_Numero_da_Semana: #N/A
Name SegmentaçãoDeDados_Numero_da_Semana1: #N/A

Sheet dashboard
B2: Análise Jogos Santa Casa
B4: Vendas | E4: Objectivos | H4: Var % | K4: Var € | N4: =esboço!F2 -> Prestação
A5: semana | C5: =esboço!B4 -> 5571.5 | D5: =IFERROR(C5/C6-1,"") -> 0.34172185 | F5: =esboço!C4 -> 4592.7 | G5: =IFERROR(F5/F6-1,"") | H5: =esboço!D4 -> 0.21312082 | L5: =esboço!E4 -> 978.8 | M5: =IFERROR(L5/L6-1,"") | O5: =esboço!F4 -> 3022.99 | P5: =IFERROR(O5/O6-1,"") -> 0.53577561
A6: semana anterior | C6: =esboço!B5 -> 4152.5 | D6: =D5 -> 0.34172185 | M6: =M5 | O6: =esboço!F5 -> 1968.38 | P6: =P5 -> 0.53577561
A7: tendencia
A8: swly | B8: =D8 -> 0.016882643 | C8: =esboço!B9 -> 5479 | D8: =IFERROR(C5/C8-1,"") -> 0.016882643 | N8: =P8 -> 0.16054146 | O8: =GETPIVOTDATA("[Measures].[PrestaçãoLYSWTD]",calc!$K$24) -> 2604.81 | P8: =IFERROR(O5/O8-1,"") -> 0.16054146
A9: mês | C9: =esboço!B6 -> 5571.5 | F9: =esboço!C6 -> 4592.7 | H9: =esboço!D6 -> 0.21312082 | L9: =esboço!E6 -> 978.8 | O9: =esboço!F6 -> 3022.99
A10: anual | C10: =esboço!B7 -> 195397 | D10: =IFERROR(C10/C11-1,"") -> -0.076538811 | F10: =esboço!C7 -> 225042.3 | H10: =esboço!D7 -> -0.13173212 | L10: =esboço!E7 -> -29645.3 | O10: =esboço!F7 -> 83585.82 | P10: =IFERROR(O10/O11-1,"") -> -0.041774046
A11: ano anterior | C11: =esboço!B8 -> 211592 | D11: =D10 -> -0.076538811 | F11: =esboço!E8 -> 0 | L11: =esboço!E8 -> 0 | O11: =GETPIVOTDATA("[Measures].[PrestaçãoLYTD]",calc!$K$24) -> 87229.76 | P11: =P10 -> -0.041774046
A13: por semana | B13: Vendas | E13: Objectivos | H13: Var % | K13: Var €
A14: =esboço!I4 -> Raspadinha | C14: =IFERROR(esboço!J4,"") -> 3440 | F14: =IFERROR(esboço!K4,"") -> 2627.7 | H14: =IFERROR(esboço!L4,"") -> 0.30912966 | I14: =esboço!L4 -> 0.30912966 | L14: =IFERROR(esboço!M4,"") -> 812.3
A15: =esboço!I5 -> Euromilhões | C15: =IFERROR(esboço!J5,"") -> 955 | F15: =IFERROR(esboço!K5,"") -> 894.25 | H15: =IFERROR(esboço!L5,"") -> 0.067934023 | I15: =esboço!L5 -> 0.067934023 | L15: =IFERROR(esboço!M5,"") -> 60.75
A16: =esboço!I6 -> Placard | C16: =IFERROR(esboço!J6,"") -> 191 | F16: =IFERROR(esboço!K6,"") -> 433.55 | H16: =IFERROR(esboço!L6,"") -> -0.55945104 | I16: =esboço!L6 -> -0.55945104 | L16: =IFERROR(esboço!M6,"") -> -242.55
A17: =esboço!I7 -> Eurodreams | C17: =IFERROR(esboço!J7,"") -> 220 | F17: =IFERROR(esboço!K7,"") -> 301.65 | H17: =IFERROR(esboço!L7,"") -> -0.27067794 | I17: =esboço!L7 -> -0.27067794 | L17: =IFERROR(esboço!M7,"") -> -81.65
A18: =esboço!I8 -> Totoloto | C18: =IFERROR(esboço!J8,"") -> 130 | F18: =IFERROR(esboço!K8,"") -> 153 | H18: =IFERROR(esboço!L8,"") -> -0.1503268 | I18: =esboço!L8 -> -0.1503268 | L18: =IFERROR(esboço!M8,"") -> -23
A19: Hípicas | C19: =IFERROR(esboço!J12,"") | F19: =IFERROR(esboço!K12,"") | I19: =IFERROR(esboço!L12,"") | L19: =IFERROR(esboço!M12,"")
A20: =esboço!I9 -> Popular | C20: =IFERROR(esboço!J9,"") -> 85 | F20: =IFERROR(esboço!K9,"") -> 107.4 | H20: =IFERROR(esboço!L9,"") -> -0.20856611 | I20: =esboço!L9 -> -0.20856611 | L20: =IFERROR(esboço!M9,"") -> -22.4
A21: =esboço!I10 -> Clássica | C21: =IFERROR(esboço!J10,"") -> 525 | F21: =IFERROR(esboço!K10,"") -> 72.15 | H21: =IFERROR(esboço!L10,"") -> 6.2765073 | I21: =esboço!L10 -> 6.2765073 | L21: =IFERROR(esboço!M10,"") -> 452.85
A22: =esboço!I11 -> Totobola | C22: =IFERROR(esboço!J11,"") -> 25.5 | F22: =IFERROR(esboço!K11,"") -> 3 | H22: =IFERROR(esboço!L11,"") -> 7.5 | I22: =esboço!L11 -> 7.5 | L22: =IFERROR(esboço!M11,"") -> 22.5
A24: por ano | B24: Vendas | E24: Objectivos | H24: Var % | K24: Var € | N24: Comissões €
A25: =esboço!I4 -> Raspadinha | C25: =esboço!P4 -> 113350 | F25: =esboço!Q4 -> 128757.3 | I25: =esboço!R4 -> -0.11966156 | L25: =esboço!S4 -> -15407.3 | O25: =esboço!T4 -> 11335
A26: =esboço!I5 -> Euromilhões | C26: =esboço!P5 -> 42000 | F26: =esboço!Q5 -> 43818.25 | I26: =esboço!R5 -> -0.041495267 | L26: =esboço!S5 -> -1818.25 | O26: =esboço!T5 -> 2100
A27: =esboço!I6 -> Placard | C27: =esboço!P6 -> 17525 | F27: =esboço!Q6 -> 21243.95 | I27: =esboço!R6 -> -0.17505925 | L27: =esboço!S6 -> -3718.95 | O27: =esboço!T6 -> 876.25
A28: =esboço!I7 -> Eurodreams | C28: =esboço!P7 -> 9587.5 | F28: =esboço!Q7 -> 14780.85 | I28: =esboço!R7 -> -0.35135665 | L28: =esboço!S7 -> -5193.35 | O28: =esboço!T7 -> 479.375
A29: =esboço!I8 -> Totoloto | C29: =esboço!P8 -> 5882 | F29: =esboço!Q8 -> 7497 | I29: =esboço!R8 -> -0.2154195 | L29: =esboço!S8 -> -1615 | O29: =esboço!T8 -> 411.74
A30: Hípicas | C30: =IFERROR(esboço!P12,"") | F30: =IFERROR(esboço!Q12,"") | I30: =IFERROR(esboço!R12,"") | L30: =IFERROR(esboço!S12,"")
A31: =esboço!I9 -> Popular | C31: =esboço!P9 -> 4381 | F31: =esboço!Q9 -> 5262.6 | I31: =esboço!R9 -> -0.16752176 | L31: =esboço!S9 -> -881.6 | O31: =esboço!T9 -> 547.625
A32: =esboço!I10 -> Clássica | C32: =esboço!P10 -> 2255 | F32: =esboço!Q10 -> 3535.35 | I32: =esboço!R10 -> -0.36215651 | L32: =esboço!S10 -> -1280.35 | O32: =esboço!T10 -> 286.385
A33: =esboço!I11 -> Totobola | C33: =esboço!P11 -> 416.5 | F33: =esboço!Q11 -> 147 | I33: =esboço!R11 -> 1.8333333 | L33: =esboço!S11 -> 269.5 | O33: =esboço!T11 -> 29.155
X36: =S38 -> 0

Sheet esboço
J1: Semanais | P1: Anuais
B2: Vendas | C2: Objectivos | D2: Var | E2: Var E | F2: Prestação | J2: Vendas | K2: Objectivos | L2: Var | M2: Var E | P2: Vendas | Q2: Objectivos | R2: Var | S2: Var E | T2: Comissão €
A3: Por data | I3: Por Jogo
A4: semana | B4: =GETPIVOTDATA("[Measures].[VendasWTD]",calc!$D$11) -> 5571.5 | C4: =GETPIVOTDATA("[Measures].[ObjectivosWTD]",calc!$D$11) -> 4592.7 | D4: =GETPIVOTDATA("[Measures].[Var%]",calc!$D$11) -> 0.21312082 | E4: =GETPIVOTDATA("[Measures].[VarEuros]",calc!$D$11) -> 978.8 | F4: =GETPIVOTDATA("[Measures].[PrestacaoWTD]",calc!$K$24) -> 3022.99 | I4: Raspadinha | J4: =IFERROR(GETPIVOTDATA("[Measures].[TotalVendas]",calc!$D$24,"[jogos].[Grupo de Jogos]","[jogos].[Grupo de Jogos].&[" & I4 &"]"),"") -> 3440 | K4: =IFERROR(GETPIVOTDATA("[Measures].[TotalObjectivos]",calc!$D$24,"[jogos].[Grupo de Jogos]","[jogos].[Grupo de Jogos].&[" & I4 &"]"),"") -> 2627.7 | L4: =IFERROR(GETPIVOTDATA("[Measures].[Var%]",calc!$D$24,"[jogos].[Grupo de Jogos]","[jogos].[Grupo de Jogos].&[" & I4 &"]"),"") -> 0.30912966 | M4: =IFERROR(GETPIVOTDATA("[Measures].[VarEuros]",calc!$D$24,"[jogos].[Grupo de Jogos]","[jogos].[Grupo de Jogos].&[" & I4 &"]"),"") -> 812.3 | P4: =GETPIVOTDATA("[Measures].[VendasYTD]",calc!$D$38,"[jogos].[Grupo de Jogos]","[jogos].[Grupo de Jogos].&[" & I4 &"]") -> 113350 | Q4: =GETPIVOTDATA("[Measures].[ObjectivosYTD]",calc!$D$38,"[jogos].[Grupo de Jogos]","[jogos].[Grupo de Jogos].&[" & I4 &"]") -> 128757.3 | R4: =GETPIVOTDATA("[Measures].[Var%]",calc!$D$38,"[jogos].[Grupo de Jogos]","[jogos].[Grupo de Jogos].&[" & I4 &"]") -> -0.11966156 | S4: =GETPIVOTDATA("[Measures].[VarEuros]",calc!$D$38,"[jogos].[Grupo de Jogos]","[jogos].[Grupo de Jogos].&[" & I4 &"]") -> -15407.3 | T4: =GETPIVOTDATA("[Measures].[ComissãoYTD]",calc!$D$38,"[jogos].[Grupo de Jogos]","[jogos].[Grupo de Jogos].&[" & I4 &"]") -> 11335
A5: semana anterior | B5: =GETPIVOTDATA("[Measures].[VendasSemanaAnterior]",calc!$B$3) -> 4152.5 | F5: =GETPIVOTDATA("[Measures].[PrestaçãoLWTD]",calc!$K$24) -> 1968.38 | I5: Euromilhões | J5: =IFERROR(GETPIVOTDATA("[Measures].[TotalVendas]",calc!$D$24,"[jogos].[Grupo de Jogos]","[jogos].[Grupo de Jogos].&[" & N5 &"]"),"") -> 955 | K5: =IFERROR(GETPIVOTDATA("[Measures].[TotalObjectivos]",calc!$D$24,"[jogos].[Grupo de Jogos]","[jogos].[Grupo de Jogos].&[" & N5 &"]"),"") -> 894.25 | L5: =IFERROR(GETPIVOTDATA("[Measures].[Var%]",calc!$D$24,"[jogos].[Grupo de Jogos]","[jogos].[Grupo de Jogos].&[" & N5 &"]"),"") -> 0.067934023 | M5: =IFERROR(GETPIVOTDATA("[Measures].[VarEuros]",calc!$D$24,"[jogos].[Grupo de Jogos]","[jogos].[Grupo de Jogos].&[" & N5 &"]"),"") -> 60.75 | N5: Euromilhões + Milhão | P5: =GETPIVOTDATA("[Measures].[VendasYTD]",calc!$D$38,"[jogos].[Grupo de Jogos]","[jogos].[Grupo de Jogos].&[" & N5 &"]") -> 42000 | Q5: =GETPIVOTDATA("[Measures].[ObjectivosYTD]",calc!$D$38,"[jogos].[Grupo de Jogos]","[jogos].[Grupo de Jogos].&[" & N5 &"]") -> 43818.25 | R5: =GETPIVOTDATA("[Measures].[Var%]",calc!$D$38,"[jogos].[Grupo de Jogos]","[jogos].[Grupo de Jogos].&[" & N5 &"]") -> -0.041495267 | S5: =GETPIVOTDATA("[Measures].[VarEuros]",calc!$D$38,"[jogos].[Grupo de Jogos]","[jogos].[Grupo de Jogos].&[" & N5 &"]") -> -1818.25 | T5: =GETPIVOTDATA("[Measures].[ComissãoYTD]",calc!$D$38,"[jogos].[Grupo de Jogos]","[jogos].[Grupo de Jogos].&[" & N5 &"]") -> 2100
A6: mês | B6: =GETPIVOTDATA("[Measures].[VendasMTD]",calc!$D$7) -> 5571.5 | C6: =GETPIVOTDATA("[Measures].[ObjectivosMTD]",calc!$D$7) -> 4592.7 | D6: =GETPIVOTDATA("[Measures].[Var%]",calc!$D$7) -> 0.21312082 | E6: =GETPIVOTDATA("[Measures].[VarEuros]",calc!$D$7) -> 978.8 | F6: =GETPIVOTDATA("[Measures].[PrestaçãoMTD]",calc!$K$24) -> 3022.99 | I6: Placard | J6: =IFERROR(GETPIVOTDATA("[Measures].[TotalVendas]",calc!$D$24,"[jogos].[Grupo de Jogos]","[jogos].[Grupo de Jogos].&[" & I6 &"]"),"") -> 191 | K6: =IFERROR(GETPIVOTDATA("[Measures].[TotalObjectivos]",calc!$D$24,"[jogos].[Grupo de Jogos]","[jogos].[Grupo de Jogos].&[" & I6 &"]"),"") -> 433.55 | L6: =IFERROR(GETPIVOTDATA("[Measures].[Var%]",calc!$D$24,"[jogos].[Grupo de Jogos]","[jogos].[Grupo de Jogos].&[" & I6 &"]"),"") -> -0.55945104 | M6: =IFERROR(GETPIVOTDATA("[Measures].[VarEuros]",calc!$D$24,"[jogos].[Grupo de Jogos]","[jogos].[Grupo de Jogos].&[" & I6 &"]"),"") -> -242.55 | P6: =IFERROR(GETPIVOTDATA("[Measures].[VendasYTD]",calc!$D$38,"[jogos].[Grupo de Jogos]","[jogos].[Grupo de Jogos].&[" & I6 &"]"),"") -> 17525 | Q6: =IFERROR(GETPIVOTDATA("[Measures].[ObjectivosYTD]",calc!$D$38,"[jogos].[Grupo de Jogos]","[jogos].[Grupo de Jogos].&[" & I6 &"]"),"") -> 21243.95 | R6: =IFERROR(GETPIVOTDATA("[Measures].[Var%]",calc!$D$38,"[jogos].[Grupo de Jogos]","[jogos].[Grupo de Jogos].&[" & I6 &"]"),"") -> -0.17505925 | S6: =IFERROR(GETPIVOTDATA("[Measures].[VarEuros]",calc!$D$38,"[jogos].[Grupo de Jogos]","[jogos].[Grupo de Jogos].&[" & I6 &"]"),"") -> -3718.95 | T6: =IFERROR(GETPIVOTDATA("[Measures].[ComissãoYTD]",calc!$D$38,"[jogos].[Grupo de Jogos]","[jogos].[Grupo de Jogos].&[" & I6 &"]"),"") -> 876.25
A7: ano | B7: =GETPIVOTDATA("[Measures].[VendasYTD]",calc!$D$3) -> 195397 | C7: =GETPIVOTDATA("[Measures].[ObjectivosYTD]",calc!$D$3) -> 225042.3 | D7: =GETPIVOTDATA("[Measures].[Var%]",calc!$D$3) -> -0.13173212 | E7: =GETPIVOTDATA("[Measures].[VarEuros]",calc!$D$3) -> -29645.3 | F7: =GETPIVOTDATA("[Measures].[PrestaçãoYTD]",calc!$K$24) -> 83585.82 | I7: Eurodreams | J7: =IFERROR(GETPIVOTDATA("[Measures].[TotalVendas]",calc!$D$24,"[jogos].[Grupo de Jogos]","[jogos].[Grupo de Jogos].&[" & I7 &"]"),"") -> 220 | K7: =IFERROR(GETPIVOTDATA("[Measures].[TotalObjectivos]",calc!$D$24,"[jogos].[Grupo de Jogos]","[jogos].[Grupo de Jogos].&[" & I7 &"]"),"") -> 301.65 | L7: =IFERROR(GETPIVOTDATA("[Measures].[Var%]",calc!$D$24,"[jogos].[Grupo de Jogos]","[jogos].[Grupo de Jogos].&[" & I7 &"]"),"") -> -0.27067794 | M7: =IFERROR(GETPIVOTDATA("[Measures].[VarEuros]",calc!$D$24,"[jogos].[Grupo de Jogos]","[jogos].[Grupo de Jogos].&[" & I7 &"]"),"") -> -81.65 | P7: =IFERROR(GETPIVOTDATA("[Measures].[VendasYTD]",calc!$D$38,"[jogos].[Grupo de Jogos]","[jogos].[Grupo de Jogos].&[" & I7 &"]"),"") -> 9587.5 | Q7: =IFERROR(GETPIVOTDATA("[Measures].[ObjectivosYTD]",calc!$D$38,"[jogos].[Grupo de Jogos]","[jogos].[Grupo de Jogos].&[" & I7 &"]"),"") -> 14780.85 | R7: =IFERROR(GETPIVOTDATA("[Measures].[Var%]",calc!$D$38,"[jogos].[Grupo de Jogos]","[jogos].[Grupo de Jogos].&[" & I7 &"]"),"") -> -0.35135665 | S7: =IFERROR(GETPIVOTDATA("[Measures].[VarEuros]",calc!$D$38,"[jogos].[Grupo de Jogos]","[jogos].[Grupo de Jogos].&[" & I7 &"]"),"") -> -5193.35 | T7: =IFERROR(GETPIVOTDATA("[Measures].[ComissãoYTD]",calc!$D$38,"[jogos].[Grupo de Jogos]","[jogos].[Grupo de Jogos].&[" & I7 &"]"),"") -> 479.375
A8: ano anterior | B8: =GETPIVOTDATA("[Measures].[VendasLYTD]",calc!$D$3) -> 211592 | I8: Totoloto | J8: =IFERROR(GETPIVOTDATA("[Measures].[TotalVendas]",calc!$D$24,"[jogos].[Grupo de Jogos]","[jogos].[Grupo de Jogos].&[" & I8 &"]"),"") -> 130 | K8: =IFERROR(GETPIVOTDATA("[Measures].[TotalObjectivos]",calc!$D$24,"[jogos].[Grupo de Jogos]","[jogos].[Grupo de Jogos].&[" & I8 &"]"),"") -> 153 | L8: =IFERROR(GETPIVOTDATA("[Measures].[Var%]",calc!$D$24,"[jogos].[Grupo de Jogos]","[jogos].[Grupo de Jogos].&[" & I8 &"]"),"") -> -0.1503268 | M8: =IFERROR(GETPIVOTDATA("[Measures].[VarEuros]",calc!$D$24,"[jogos].[Grupo de Jogos]","[jogos].[Grupo de Jogos].&[" & I8 &"]"),"") -> -23 | P8: =IFERROR(GETPIVOTDATA("[Measures].[VendasYTD]",calc!$D$38,"[jogos].[Grupo de Jogos]","[jogos].[Grupo de Jogos].&[" & I8 &"]"),"") -> 5882 | Q8: =IFERROR(GETPIVOTDATA("[Measures].[ObjectivosYTD]",calc!$D$38,"[jogos].[Grupo de Jogos]","[jogos].[Grupo de Jogos].&[" & I8 &"]"),"") -> 7497 | R8: =IFERROR(GETPIVOTDATA("[Measures].[Var%]",calc!$D$38,"[jogos].[Grupo de Jogos]","[jogos].[Grupo de Jogos].&[" & I8 &"]"),"") -> -0.2154195 | S8: =IFERROR(GETPIVOTDATA("[Measures].[VarEuros]",calc!$D$38,"[jogos].[Grupo de Jogos]","[jogos].[Grupo de Jogos].&[" & I8 &"]"),"") -> -1615 | T8: =IFERROR(GETPIVOTDATA("[Measures].[ComissãoYTD]",calc!$D$38,"[jogos].[Grupo de Jogos]","[jogos].[Grupo de Jogos].&[" & I8 &"]"),"") -> 411.74
A9: swly | B9: =GETPIVOTDATA("[Measures].[VendasLYSWTD]",calc!$D$15) -> 5479 | I9: Popular | J9: =IFERROR(GETPIVOTDATA("[Measures].[TotalVendas]",calc!$D$24,"[jogos].[Grupo de Jogos]","[jogos].[Grupo de Jogos].&[" & I9 &"]"),"") -> 85 | K9: =IFERROR(GETPIVOTDATA("[Measures].[TotalObjectivos]",calc!$D$24,"[jogos].[Grupo de Jogos]","[jogos].[Grupo de Jogos].&[" & I9 &"]"),"") -> 107.4 | L9: =IFERROR(GETPIVOTDATA("[Measures].[Var%]",calc!$D$24,"[jogos].[Grupo de Jogos]","[jogos].[Grupo de Jogos].&[" & I9 &"]"),"") -> -0.20856611 | M9: =IFERROR(GETPIVOTDATA("[Measures].[VarEuros]",calc!$D$24,"[jogos].[Grupo de Jogos]","[jogos].[Grupo de Jogos].&[" & I9 &"]"),"") -> -22.4 | P9: =IFERROR(GETPIVOTDATA("[Measures].[VendasYTD]",calc!$D$38,"[jogos].[Grupo de Jogos]","[jogos].[Grupo de Jogos].&[" & I9 &"]"),"") -> 4381 | Q9: =IFERROR(GETPIVOTDATA("[Measures].[ObjectivosYTD]",calc!$D$38,"[jogos].[Grupo de Jogos]","[jogos].[Grupo de Jogos].&[" & I9 &"]"),"") -> 5262.6 | R9: =IFERROR(GETPIVOTDATA("[Measures].[Var%]",calc!$D$38,"[jogos].[Grupo de Jogos]","[jogos].[Grupo de Jogos].&[" & I9 &"]"),"") -> -0.16752176 | S9: =IFERROR(GETPIVOTDATA("[Measures].[VarEuros]",calc!$D$38,"[jogos].[Grupo de Jogos]","[jogos].[Grupo de Jogos].&[" & I9 &"]"),"") -> -881.6 | T9: =IFERROR(GETPIVOTDATA("[Measures].[ComissãoYTD]",calc!$D$38,"[jogos].[Grupo de Jogos]","[jogos].[Grupo de Jogos].&[" & I9 &"]"),"") -> 547.625
I10: Clássica | J10: =IFERROR(GETPIVOTDATA("[Measures].[TotalVendas]",calc!$D$24,"[jogos].[Grupo de Jogos]","[jogos].[Grupo de Jogos].&[" & I10 &"]"),"") -> 525 | K10: =IFERROR(GETPIVOTDATA("[Measures].[TotalObjectivos]",calc!$D$24,"[jogos].[Grupo de Jogos]","[jogos].[Grupo de Jogos].&[" & I10 &"]"),"") -> 72.15 | L10: =IFERROR(GETPIVOTDATA("[Measures].[Var%]",calc!$D$24,"[jogos].[Grupo de Jogos]","[jogos].[Grupo de Jogos].&[" & I10 &"]"),"") -> 6.2765073 | M10: =IFERROR(GETPIVOTDATA("[Measures].[VarEuros]",calc!$D$24,"[jogos].[Grupo de Jogos]","[jogos].[Grupo de Jogos].&[" & I10 &"]"),"") -> 452.85 | P10: =IFERROR(GETPIVOTDATA("[Measures].[VendasYTD]",calc!$D$38,"[jogos].[Grupo de Jogos]","[jogos].[Grupo de Jogos].&[" & I10 &"]"),"") -> 2255 | Q10: =IFERROR(GETPIVOTDATA("[Measures].[ObjectivosYTD]",calc!$D$38,"[jogos].[Grupo de Jogos]","[jogos].[Grupo de Jogos].&[" & I10 &"]"),"") -> 3535.35 | R10: =IFERROR(GETPIVOTDATA("[Measures].[Var%]",calc!$D$38,"[jogos].[Grupo de Jogos]","[jogos].[Grupo de Jogos].&[" & I10 &"]"),"") -> -0.36215651 | S10: =IFERROR(GETPIVOTDATA("[Measures].[VarEuros]",calc!$D$38,"[jogos].[Grupo de Jogos]","[jogos].[Grupo de Jogos].&[" & I10 &"]"),"") -> -1280.35 | T10: =IFERROR(GETPIVOTDATA("[Measures].[ComissãoYTD]",calc!$D$38,"[jogos].[Grupo de Jogos]","[jogos].[Grupo de Jogos].&[" & I10 &"]"),"") -> 286.385
I11: Totobola | J11: =IFERROR(GETPIVOTDATA("[Measures].[TotalVendas]",calc!$D$24,"[jogos].[Grupo de Jogos]","[jogos].[Grupo de Jogos].&[" & I11 &"]"),"") -> 25.5 | K11: =IFERROR(GETPIVOTDATA("[Measures].[TotalObjectivos]",calc!$D$24,"[jogos].[Grupo de Jogos]","[jogos].[Grupo de Jogos].&[" & I11 &"]"),"") -> 3 | L11: =IFERROR(GETPIVOTDATA("[Measures].[Var%]",calc!$D$24,"[jogos].[Grupo de Jogos]","[jogos].[Grupo de Jogos].&[" & I11 &"]"),"") -> 7.5 | M11: =IFERROR(GETPIVOTDATA("[Measures].[VarEuros]",calc!$D$24,"[jogos].[Grupo de Jogos]","[jogos].[Grupo de Jogos].&[" & I11 &"]"),"") -> 22.5 | P11: =IFERROR(GETPIVOTDATA("[Measures].[VendasYTD]",calc!$D$38,"[jogos].[Grupo de Jogos]","[jogos].[Grupo de Jogos].&[" & I11 &"]"),"") -> 416.5 | Q11: =IFERROR(GETPIVOTDATA("[Measures].[ObjectivosYTD]",calc!$D$38,"[jogos].[Grupo de Jogos]","[jogos].[Grupo de Jogos].&[" & I11 &"]"),"") -> 147 | R11: =IFERROR(GETPIVOTDATA("[Measures].[Var%]",calc!$D$38,"[jogos].[Grupo de Jogos]","[jogos].[Grupo de Jogos].&[" & I11 &"]"),"") -> 1.8333333 | S11: =IFERROR(GETPIVOTDATA("[Measures].[VarEuros]",calc!$D$38,"[jogos].[Grupo de Jogos]","[jogos].[Grupo de Jogos].&[" & I11 &"]"),"") -> 269.5 | T11: =IFERROR(GETPIVOTDATA("[Measures].[ComissãoYTD]",calc!$D$38,"[jogos].[Grupo de Jogos]","[jogos].[Grupo de Jogos].&[" & I11 &"]"),"") -> 29.155
I12: Hipicas | J12: =IFERROR(GETPIVOTDATA("[Measures].[TotalVendas]",calc!$D$24,"[jogos].[Grupo de Jogos]","[jogos].[Grupo de Jogos].&[" & I12 &"]"),"") | K12: =IFERROR(GETPIVOTDATA("[Measures].[TotalObjectivos]",calc!$D$24,"[jogos].[Grupo de Jogos]","[jogos].[Grupo de Jogos].&[" & I12 &"]"),"") | L12: =IFERROR(GETPIVOTDATA("[Measures].[Var%]",calc!$D$24,"[jogos].[Grupo de Jogos]","[jogos].[Grupo de Jogos].&[" & I12 &"]"),"") | M12: =IFERROR(GETPIVOTDATA("[Measures].[VarEuros]",calc!$D$24,"[jogos].[Grupo de Jogos]","[jogos].[Grupo de Jogos].&[" & I12 &"]"),"") | P12: =IFERROR(GETPIVOTDATA("[Measures].[VendasYTD]",calc!$D$38,"[jogos].[Grupo de Jogos]","[jogos].[Grupo de Jogos].&[" & I12 &"]"),"") | Q12: =IFERROR(GETPIVOTDATA("[Measures].[ObjectivosYTD]",calc!$D$38,"[jogos].[Grupo de Jogos]","[jogos].[Grupo de Jogos].&[" & I12 &"]"),"") | R12: =IFERROR(GETPIVOTDATA("[Measures].[Var%]",calc!$D$38,"[jogos].[Grupo de Jogos]","[jogos].[Grupo de Jogos].&[" & I12 &"]"),"") | S12: =IFERROR(GETPIVOTDATA("[Measures].[VarEuros]",calc!$D$38,"[jogos].[Grupo de Jogos]","[jogos].[Grupo de Jogos].&[" & I12 &"]"),"") | T12: =IFERROR(GETPIVOTDATA("[Measures].[ComissãoYTD]",calc!$D$38,"[jogos].[Grupo de Jogos]","[jogos].[Grupo de Jogos].&[" & I12 &"]"),"")

Sheet vendas vs objectivos
B14: Semana | C14: TotalVendas
B15: janeiro
B16: 1 | C16: 5082
B17: 2 | C17: 5493.5
B18: 3 | C18: 3350
B19: 4 | C19: 5390.5
B20: 5 | C20: 5130
B21: fevereiro
B22: 6 | C22: 3575
B23: 7 | C23: 4797
B24: 8 | C24: 3072.5
B25: 9 | C25: 3291
B26: março
B27: 10 | C27: 4800
B28: 11 | C28: 5052.5
B29: 12 | C29: 5142
B30: 13 | C30: 3928
B31: abril
B32: 14 | C32: 2996
B33: 15 | C33: 3043.5
B34: 16 | C34: 2798.5
B35: 17 | C35: 3041
B36: maio
B37: 18 | C37: 4256.5
B38: 19 | C38: 3338
B39: 20 | C39: 4144
B40: 21 | C40: 4547
B41: 22 | C41: 4880
B42: junho
B43: 23 | C43: 3461.5
B44: 24 | C44: 3918.5
B45: 25 | C45: 3260.5
B46: 26 | C46: 4553.5
B47: julho
B48: 27 | C48: 3003.5
B49: 28 | C49: 4386.5
B50: 29 | C50: 3092.5
B51: 30 | C51: 4542.5
B52: agosto
B53: 31 | C53: 3806
...

Sheet vendas por semana
B3: Semana | C3: Soma de Vendas
B4: janeiro
B5: 1 | C5: 5082
B6: 2 | C6: 5493.5
B7: 3 | C7: 3350
B8: 4 | C8: 5390.5
B9: 5 | C9: 5130
B10: fevereiro
B11: 6 | C11: 3575
B12: 7 | C12: 4797
B13: 8 | C13: 3072.5
B14: 9 | C14: 3291
B15: março
B16: 10 | C16: 4800
B17: 11 | C17: 5052.5
B18: 12 | C18: 5142
B19: 13 | C19: 3928
B20: abril
B21: 14 | C21: 2996
B22: 15 | C22: 3043.5
B23: 16 | C23: 2798.5
B24: 17 | C24: 3041
B25: maio
B26: 18 | C26: 4256.5
B27: 19 | C27: 3338
B28: 20 | C28: 4144
B29: 21 | C29: 4547
B30: 22 | C30: 4880
B31: junho
B32: 23 | C32: 3461.5
B33: 24 | C33: 3918.5
B34: 25 | C34: 3260.5
B35: 26 | C35: 4553.5
B36: julho
B37: 27 | C37: 3003.5
B38: 28 | C38: 4386.5
B39: 29 | C39: 3092.5
B40: 30 | C40: 4542.5
B41: agosto
B42: 31 | C42: 3806
...

Sheet Lucro
B2: Jogo | C2: Vendas | D2: Comissões | E2: Total Apurado
B3: =dashboard!A25 -> Raspadinha | C3: =dashboard!C25 -> 113350 | D3: 0.1 | E3: =C3*D3 -> 11335
B4: =dashboard!A26 -> Euromilhões | C4: =dashboard!C26 -> 42000 | D4: 0.05 | E4: =C4*D4 -> 2100
B5: =dashboard!A27 -> Placard | C5: =dashboard!C27 -> 17525 | D5: 0.05 | E5: =C5*D5 -> 876.25
B6: =dashboard!A28 -> Eurodreams | C6: =dashboard!C28 -> 9587.5 | D6: 0.05 | E6: =C6*D6 -> 479.375
B7: =dashboard!A29 -> Totoloto | C7: =dashboard!C29 -> 5882 | D7: 0.07 | E7: =C7*D7 -> 411.74
B8: =dashboard!A31 -> Popular | C8: =dashboard!C31 -> 4381 | D8: 0.125 | E8: =C8*D8 -> 547.625
B9: =dashboard!A32 -> Clássica | C9: =dashboard!C32 -> 2255 | D9: 0.127 | E9: =C9*D9 -> 286.385
B10: =dashboard!A33 -> Totobola | C10: =dashboard!C33 -> 416.5 | D10: 0.07 | E10: =C10*D10 -> 29.155
B11: Total | C11: =SUBTOTAL(109,Tabela1[Vendas]) -> 195397 | D11: =SUBTOTAL(101,Tabela1[Comissões]) -> 0.08025 | E11: =SUBTOTAL(109,Tabela1[Total Apurado]) -> 16065.53

Sheet calc
B3: VendasSemanaAnterior | D3: VendasYTD | E3: ObjectivosYTD | F3: Var% | G3: VarEuros | H3: VendasLYTD | K3: TotalVendas
B4: 4152.5 | D4: 195397 | E4: 225042.3 | F4: -0.13173212 | G4: -29645.3 | H4: 211592 | K4: 195397
D7: VendasMTD | E7: ObjectivosMTD | F7: Var% | G7: VarEuros
D8: 5571.5 | E8: 4592.7 | F8: 0.21312082 | G8: 978.8
D11: VendasWTD | E11: ObjectivosWTD | F11: Var% | G11: VarEuros
D12: 5571.5 | E12: 4592.7 | F12: 0.21312082 | G12: 978.8
D15: VendasLWTD | E15: VendasLYSWTD
D16: 4152.5 | E16: 5479
D24: Rótulos de Linha | E24: TotalVendas | F24: TotalObjectivos | G24: Var% | H24: VarEuros | K24: PrestaçãoYTD | L24: PrestaçãoMTD | M24: PrestacaoWTD | N24: PrestaçãoLWTD | O24: PrestaçãoLYTD | P24: PrestaçãoLYSWTD
D25: Raspadinha | E25: 3440 | F25: 2627.7 | G25: 0.30912966 | H25: 812.3 | K25: 83585.82 | L25: 3022.99 | M25: 3022.99 | N25: 1968.38 | O25: 87229.76 | P25: 2604.81
D26: Euromilhões + Milhão | E26: 955 | F26: 894.25 | G26: 0.067934023 | H26: 60.75
D27: Clássica | E27: 525 | F27: 72.15 | G27: 6.2765073 | H27: 452.85
D28: Eurodreams | E28: 220 | F28: 301.65 | G28: -0.27067794 | H28: -81.65
D29: Placard | E29: 191 | F29: 433.55 | G29: -0.55945104 | H29: -242.55
D30: Totoloto | E30: 130 | F30: 153 | G30: -0.1503268 | H30: -23
D31: Popular | E31: 85 | F31: 107.4 | G31: -0.20856611 | H31: -22.4
D32: Totobola | E32: 25.5 | F32: 3 | G32: 7.5 | H32: 22.5
D33: (em branco) | E33: 0 | G33: #NUM! | H33: 0
D34: Total Geral | E34: 5571.5 | F34: 4592.7 | G34: 0.21312082 | H34: 978.8
D38: Rótulos de Linha | E38: VendasYTD | F38: ObjectivosYTD | G38: Var% | H38: VarEuros | I38: ComissãoYTD
D39: Raspadinha | E39: 113350 | F39: 128757.3 | G39: -0.11966156 | H39: -15407.3 | I39: 11335
D40: Euromilhões + Milhão | E40: 42000 | F40: 43818.25 | G40: -0.041495267 | H40: -1818.25 | I40: 2100
D41: Placard | E41: 17525 | F41: 21243.95 | G41: -0.17505925 | H41: -3718.95 | I41: 876.25
D42: Eurodreams | E42: 9587.5 | F42: 14780.85 | G42: -0.35135665 | H42: -5193.35 | I42: 479.375
D43: Totoloto | E43: 5882 | F43: 7497 | G43: -0.2154195 | H43: -1615 | I43: 411.74
D44: Popular | E44: 4381 | F44: 5262.6 | G44: -0.16752176 | H44: -881.6 | I44: 547.625
D45: Clássica | E45: 2255 | F45: 3535.35 | G45: -0.36215651 | H45: -1280.35 | I45: 286.385
D46: Totobola | E46: 416.5 | F46: 147 | G46: 1.8333333 | H46: 269.5 | I46: 29.155
D47: (em branco) | E47: 0 | G47: #NUM! | H47: 0
D48: Total Geral | E48: 195397 | F48: 225042.3 | G48: -0.13173212 | H48: -29645.3 | I48: 16065.53

Sheet sparkline
B3: Rótulos de Linha | C3: TotalVendas
B4: 49 | C4: 5571.5
B5: 48 | C5: 4152.5
B6: 47 | C6: 4481.5
B7: 46 | C7: 4236
B8: 45 | C8: 4298
B9: 44 | C9: 2570.5
B10: 43 | C10: 4262
B11: 42 | C11: 4279
B12: 41 | C12: 4906
B13: 40 | C13: 4657.5
B14: 39 | C14: 4831
B15: 38 | C15: 4497
... B52: 1 | C52: 5082
B53: Total Geral | C53: 195397
